{"name": "Создание пользователя с повторными данными", "status": "passed", "description": "Проверяем создание пользователя с использованием уже существующих данных и получаем ошибку", "start": 1723733796935, "stop": 1723733798306, "uuid": "f70c75d9-ee55-47b5-8ae9-4c37a19a4de2", "historyId": "ff18c0c774f57977f0c3b596dadc7845", "testCaseId": "ff18c0c774f57977f0c3b596dadc7845", "fullName": "tests.test_create_user.TestCreateUser#test_create_already_existing_user_fail", "labels": [{"name": "parentSuite", "value": "tests"}, {"name": "suite", "value": "test_create_user"}, {"name": "subSuite", "value": "TestCreateUser"}, {"name": "host", "value": "DESKTOP-LQ0DQPC"}, {"name": "thread", "value": "20004-MainThread"}, {"name": "framework", "value": "pytest"}, {"name": "language", "value": "cpython3"}, {"name": "package", "value": "tests.test_create_user"}]}